<mujoco model="ar4_mk3">
    <compiler angle="radian" autolimits="true"/>
    <option timestep="0.002" integrator="implicitfast">
        <flag contact="enable" multiccd="enable"/>
    </option>
    <!-- <statistic meansize="0.116999" extent="0.779996" center="0.0273132 -0.0950417 0.259419"/> -->
    <asset>
        <material name="white" rgba="1 1 1 1"/>
        <material name="red" rgba="1 0 0 1"/>
        <material name="blue" rgba="0 0 1 1"/>
        <material name="black" rgba="0 0 0 1"/>
        <material name="gray" rgba="0.753 0.753 0.753 1"/>
        <material name="transparent" rgba="0 0 0 0"/>
        <!-- Wiring-harness tubes. Slight sheen so black tubing/heat-shrink reads
             as rubber/plastic rather than flat matte. geom_rgba (set per segment
             at runtime) overrides the albedo; this material only supplies the
             finish. -->
        <material name="cable_mat" specular="0.4" shininess="0.3" reflectance="0.02" rgba="0.05 0.05 0.05 1"/>
        <!-- texrepeat tiles the texture across each link's bbox so 1K source
             textures stay sharp on ~10-20 cm parts. texuniform stays false
             (default) so the projection is bbox-relative and the texture
             travels with the link instead of swimming past it during motion. -->
        <material name="base_link_mat" texrepeat="3 3" rgba="1 1 1 1"/>
        <material name="link_1_mat" texrepeat="3 3" rgba="1 1 1 1"/>
        <material name="link_2_mat" texrepeat="3 3" rgba="1 1 1 1"/>
        <material name="link_3_mat" texrepeat="3 3" rgba="1 1 1 1"/>
        <material name="link_4_mat" texrepeat="3 3" rgba="1 1 1 1"/>
        <material name="link_5_mat" texrepeat="3 3" rgba="1 1 1 1"/>
        <material name="link_6_mat" texrepeat="3 3" rgba="1 1 1 1"/>
        <material name="gripper_base_link_mat" texrepeat="2 2" rgba="1 1 1 1"/>
        <material name="gripper_jaw1_mat" texrepeat="2 2" rgba="0.149 0.149 0.149 1"/>
        <material name="gripper_jaw2_mat" texrepeat="2 2" rgba="0.149 0.149 0.149 1"/>
        <material name="block_mat" specular="0" shininess="0.5" reflectance="0" rgba="0.2 0.2 0.2 1"></material>
        <material name="target_mat" specular="0" shininess="0.5" reflectance="0" rgba="1 0 0 0.5"/>
        <material name="distractor1_mat" specular="0" shininess="0.5" reflectance="0" rgba="0 1 0 0.5"/>
        <material name="distractor2_mat" specular="0" shininess="0.5" reflectance="0" rgba="0 0 1 0.5"/>
        <material name="object_mat" specular="0" shininess="0.5" reflectance="0" rgba="1 1 0 1"/>
        <material name="object_distractor1_mat" specular="0" shininess="0.5" reflectance="0" rgba="0 1 0 1"/>
        <material name="object_distractor2_mat" specular="0" shininess="0.5" reflectance="0" rgba="0 0 1 1"/>

        <mesh name="base_link" file="assets/base_link.STL"/>
        <mesh name="link_1" file="assets/link_1.STL"/>
        <mesh name="link_2" file="assets/link_2.STL"/>
        <mesh name="link_3" file="assets/link_3.STL"/>
        <mesh name="link_4" file="assets/link_4.STL"/>
        <mesh name="link_5" file="assets/link_5.STL"/>
        <mesh name="link_6" file="assets/link_6.STL"/>
        <mesh name="gripper_base_link" file="assets/gripper_base_link.stl"/>
        <mesh name="gripper_jaw1_link" file="assets/gripper_jaw1_link.stl"/>
        <mesh name="gripper_jaw2_link" file="assets/gripper_jaw2_link.stl"/>
        <!-- Pickable-block visual presets (visual only; collision stays the box
             geom). Each preset = one of the 6 edge OBJs (generated by
             scripts/generate_pla_block_mesh.py, authored at unit half-extent,
             carrying UVs for the layer texture) at one of 5 scales. The DR pass
             shows one preset geom per block per episode and scales the collision
             box to match. Mesh names / scales must match PLA_BLOCK_PRESETS in
             ar4_mk3_config.py. -->
        <mesh name="pla_block_p0" file="assets/pla_block_chamfer_s.obj" scale="0.0095 0.0095 0.0095"/>
        <mesh name="pla_block_p1" file="assets/pla_block_chamfer_m.obj" scale="0.011 0.011 0.011"/>
        <mesh name="pla_block_p2" file="assets/pla_block_chamfer_l.obj" scale="0.012 0.012 0.012"/>
        <mesh name="pla_block_p3" file="assets/pla_block_fillet_s.obj" scale="0.0135 0.0135 0.0135"/>
        <mesh name="pla_block_p4" file="assets/pla_block_fillet_m.obj" scale="0.015 0.015 0.015"/>
        <mesh name="pla_block_p5" file="assets/pla_block_fillet_l.obj" scale="0.0095 0.0095 0.0095"/>
        <mesh name="pla_block_p6" file="assets/pla_block_chamfer_s.obj" scale="0.011 0.011 0.011"/>
        <mesh name="pla_block_p7" file="assets/pla_block_chamfer_m.obj" scale="0.012 0.012 0.012"/>
        <mesh name="pla_block_p8" file="assets/pla_block_chamfer_l.obj" scale="0.0135 0.0135 0.0135"/>
        <mesh name="pla_block_p9" file="assets/pla_block_fillet_s.obj" scale="0.015 0.015 0.015"/>
        <mesh name="pla_block_p10" file="assets/pla_block_fillet_m.obj" scale="0.0095 0.0095 0.0095"/>
        <mesh name="pla_block_p11" file="assets/pla_block_fillet_l.obj" scale="0.011 0.011 0.011"/>
        <mesh name="pla_block_p12" file="assets/pla_block_chamfer_s.obj" scale="0.012 0.012 0.012"/>
        <mesh name="pla_block_p13" file="assets/pla_block_chamfer_m.obj" scale="0.0135 0.0135 0.0135"/>
        <mesh name="pla_block_p14" file="assets/pla_block_chamfer_l.obj" scale="0.015 0.015 0.015"/>
    </asset>

    <default>
        <default class="ar4_mk3">
            <material specular="0.5" shininess="0.25"/>
            <joint axis="0 1 0" range="-6.28319 6.28319" armature="0.1"/>
            <position ctrlrange="-6.2831 6.2831"/>
            <general biastype="affine" ctrlrange="-6.2831 6.2831" gainprm="1000" biasprm="0 -1000 -100"/>
            <default class="size5">
                <joint damping="0"/>
                <general forcerange="-330 330" gainprm="0"/>
            </default>
            <default class="size4">
                <joint damping="20"/>
                <general forcerange="-330 330" gainprm="0"/>
            </default>
            <default class="size3">
                <joint damping="10"/>
                <general forcerange="-150 150" gainprm="0"/>
            </default>
            <default class="size2">
                <joint damping="4"/>
                <general forcerange="-56 56" gainprm="0"/>
            </default>
            <default class="size1">
                <joint damping="10"/>
                <general forcerange="-56 56" gainprm="50" biasprm="0 -50 -5" ctrlrange="-0.014 0"/>
            </default>
            <default class="visual">
                <geom type="mesh" contype="0" conaffinity="0" group="2"/>
            </default>
            <default class="collision">
                <geom type="capsule" group="3"/>
                <default class="eef_collision">
                    <geom type="cylinder"/>
                </default>
            </default>
            <default class="position">
              <position kp="20000" kv="250" forcerange="-1000 1000"/>
              <default class="position3">
                <position kp="5000" kv="60" forcerange="-200 200"/>
              </default>
            </default>
        </default>
    </default>

    <worldbody>
        <body name="target_visual_body" pos="0.2 0.2 0">
            <geom name="target_visual" type="box" size="0.025 0.025 0.001" pos="0 0 0.0" material="target_mat" contype="0" conaffinity="0" group="2"/>
        </body>
        <body name="target_distractor1_visual_body" pos="0.3 0.3 0">
            <geom name="distractor1_visual" type="box" size="0.025 0.025 0.001" pos="0 0 0.0" material="distractor1_mat" contype="0" conaffinity="0" group="2"/>
        </body>
        <body name="target_distractor2_visual_body" pos="0.4 0.4 0">
            <geom name="distractor2_visual" type="box" size="0.025 0.025 0.001" pos="0 0 0.0" material="distractor2_mat" contype="0" conaffinity="0" group="2"/>
        </body>
        <site name="target0" pos="0.2 0.2 0" size="0.005" rgba="0 0 0 0" type="sphere"/>
        <!-- Each pickable block: an invisible collision box (unchanged grasp
             physics) plus a chamfered visual mesh carrying the PLA material. The
             box keeps the geom name so dynamics DR (friction/mass) still targets
             it; the mesh geom has mass="0" so body inertia is unchanged. -->
        <body name="object0" pos="-0.15 -0.3 0.2">
          <joint name="object0:joint" type="free" damping="0"></joint>
          <geom size="0.012 0.012 0.012" type="box" condim="3" name="object0" rgba="0 0 0 0" mass="0.1"
            friction="2.0 0.5 0.1" contype="1" conaffinity="1" solref="0.004 1" solimp="0.95 0.99 0.001 0.5 2"/>
          <geom name="object0_visual_p0" type="mesh" mesh="pla_block_p0" material="object_mat" mass="0" contype="0" conaffinity="0" group="2"/>
          <geom name="object0_visual_p1" type="mesh" mesh="pla_block_p1" material="object_mat" mass="0" contype="0" conaffinity="0" group="2" rgba="1 1 1 0"/>
          <geom name="object0_visual_p2" type="mesh" mesh="pla_block_p2" material="object_mat" mass="0" contype="0" conaffinity="0" group="2" rgba="1 1 1 0"/>
          <geom name="object0_visual_p3" type="mesh" mesh="pla_block_p3" material="object_mat" mass="0" contype="0" conaffinity="0" group="2" rgba="1 1 1 0"/>
          <geom name="object0_visual_p4" type="mesh" mesh="pla_block_p4" material="object_mat" mass="0" contype="0" conaffinity="0" group="2" rgba="1 1 1 0"/>
          <geom name="object0_visual_p5" type="mesh" mesh="pla_block_p5" material="object_mat" mass="0" contype="0" conaffinity="0" group="2" rgba="1 1 1 0"/>
          <geom name="object0_visual_p6" type="mesh" mesh="pla_block_p6" material="object_mat" mass="0" contype="0" conaffinity="0" group="2" rgba="1 1 1 0"/>
          <geom name="object0_visual_p7" type="mesh" mesh="pla_block_p7" material="object_mat" mass="0" contype="0" conaffinity="0" group="2" rgba="1 1 1 0"/>
          <geom name="object0_visual_p8" type="mesh" mesh="pla_block_p8" material="object_mat" mass="0" contype="0" conaffinity="0" group="2" rgba="1 1 1 0"/>
          <geom name="object0_visual_p9" type="mesh" mesh="pla_block_p9" material="object_mat" mass="0" contype="0" conaffinity="0" group="2" rgba="1 1 1 0"/>
          <geom name="object0_visual_p10" type="mesh" mesh="pla_block_p10" material="object_mat" mass="0" contype="0" conaffinity="0" group="2" rgba="1 1 1 0"/>
          <geom name="object0_visual_p11" type="mesh" mesh="pla_block_p11" material="object_mat" mass="0" contype="0" conaffinity="0" group="2" rgba="1 1 1 0"/>
          <geom name="object0_visual_p12" type="mesh" mesh="pla_block_p12" material="object_mat" mass="0" contype="0" conaffinity="0" group="2" rgba="1 1 1 0"/>
          <geom name="object0_visual_p13" type="mesh" mesh="pla_block_p13" material="object_mat" mass="0" contype="0" conaffinity="0" group="2" rgba="1 1 1 0"/>
          <geom name="object0_visual_p14" type="mesh" mesh="pla_block_p14" material="object_mat" mass="0" contype="0" conaffinity="0" group="2" rgba="1 1 1 0"/>
          <site name="object0" pos="0 0 0" size="0.002 0.002 0.002" rgba="1 0 0 1" type="sphere"></site>
        </body>
        <body name="object_distractor1" pos="-0.15 -0.3 0.2">
          <joint name="object_distractor1:joint" type="free" damping="0"></joint>
          <geom size="0.012 0.012 0.012" type="box" condim="3" name="object_distractor1" rgba="0 0 0 0" mass="0.1"
            friction="2.0 0.5 0.1" contype="1" conaffinity="1" solref="0.004 1" solimp="0.95 0.99 0.001 0.5 2"/>
          <geom name="object_distractor1_visual_p0" type="mesh" mesh="pla_block_p0" material="object_distractor1_mat" mass="0" contype="0" conaffinity="0" group="2"/>
          <geom name="object_distractor1_visual_p1" type="mesh" mesh="pla_block_p1" material="object_distractor1_mat" mass="0" contype="0" conaffinity="0" group="2" rgba="1 1 1 0"/>
          <geom name="object_distractor1_visual_p2" type="mesh" mesh="pla_block_p2" material="object_distractor1_mat" mass="0" contype="0" conaffinity="0" group="2" rgba="1 1 1 0"/>
          <geom name="object_distractor1_visual_p3" type="mesh" mesh="pla_block_p3" material="object_distractor1_mat" mass="0" contype="0" conaffinity="0" group="2" rgba="1 1 1 0"/>
          <geom name="object_distractor1_visual_p4" type="mesh" mesh="pla_block_p4" material="object_distractor1_mat" mass="0" contype="0" conaffinity="0" group="2" rgba="1 1 1 0"/>
          <geom name="object_distractor1_visual_p5" type="mesh" mesh="pla_block_p5" material="object_distractor1_mat" mass="0" contype="0" conaffinity="0" group="2" rgba="1 1 1 0"/>
          <geom name="object_distractor1_visual_p6" type="mesh" mesh="pla_block_p6" material="object_distractor1_mat" mass="0" contype="0" conaffinity="0" group="2" rgba="1 1 1 0"/>
          <geom name="object_distractor1_visual_p7" type="mesh" mesh="pla_block_p7" material="object_distractor1_mat" mass="0" contype="0" conaffinity="0" group="2" rgba="1 1 1 0"/>
          <geom name="object_distractor1_visual_p8" type="mesh" mesh="pla_block_p8" material="object_distractor1_mat" mass="0" contype="0" conaffinity="0" group="2" rgba="1 1 1 0"/>
          <geom name="object_distractor1_visual_p9" type="mesh" mesh="pla_block_p9" material="object_distractor1_mat" mass="0" contype="0" conaffinity="0" group="2" rgba="1 1 1 0"/>
          <geom name="object_distractor1_visual_p10" type="mesh" mesh="pla_block_p10" material="object_distractor1_mat" mass="0" contype="0" conaffinity="0" group="2" rgba="1 1 1 0"/>
          <geom name="object_distractor1_visual_p11" type="mesh" mesh="pla_block_p11" material="object_distractor1_mat" mass="0" contype="0" conaffinity="0" group="2" rgba="1 1 1 0"/>
          <geom name="object_distractor1_visual_p12" type="mesh" mesh="pla_block_p12" material="object_distractor1_mat" mass="0" contype="0" conaffinity="0" group="2" rgba="1 1 1 0"/>
          <geom name="object_distractor1_visual_p13" type="mesh" mesh="pla_block_p13" material="object_distractor1_mat" mass="0" contype="0" conaffinity="0" group="2" rgba="1 1 1 0"/>
          <geom name="object_distractor1_visual_p14" type="mesh" mesh="pla_block_p14" material="object_distractor1_mat" mass="0" contype="0" conaffinity="0" group="2" rgba="1 1 1 0"/>
          <site name="object_distractor1" pos="0 0 0" size="0.002 0.002 0.002" rgba="0 1 0 1" type="sphere"></site>
        </body>
        <body name="object_distractor2" pos="-0.15 -0.3 0.2">
          <joint name="object_distractor2:joint" type="free" damping="0"></joint>
          <geom size="0.012 0.012 0.012" type="box" condim="3" name="object_distractor2" rgba="0 0 0 0" mass="0.1"
            friction="2.0 0.5 0.1" contype="1" conaffinity="1" solref="0.004 1" solimp="0.95 0.99 0.001 0.5 2"/>
          <geom name="object_distractor2_visual_p0" type="mesh" mesh="pla_block_p0" material="object_distractor2_mat" mass="0" contype="0" conaffinity="0" group="2"/>
          <geom name="object_distractor2_visual_p1" type="mesh" mesh="pla_block_p1" material="object_distractor2_mat" mass="0" contype="0" conaffinity="0" group="2" rgba="1 1 1 0"/>
          <geom name="object_distractor2_visual_p2" type="mesh" mesh="pla_block_p2" material="object_distractor2_mat" mass="0" contype="0" conaffinity="0" group="2" rgba="1 1 1 0"/>
          <geom name="object_distractor2_visual_p3" type="mesh" mesh="pla_block_p3" material="object_distractor2_mat" mass="0" contype="0" conaffinity="0" group="2" rgba="1 1 1 0"/>
          <geom name="object_distractor2_visual_p4" type="mesh" mesh="pla_block_p4" material="object_distractor2_mat" mass="0" contype="0" conaffinity="0" group="2" rgba="1 1 1 0"/>
          <geom name="object_distractor2_visual_p5" type="mesh" mesh="pla_block_p5" material="object_distractor2_mat" mass="0" contype="0" conaffinity="0" group="2" rgba="1 1 1 0"/>
          <geom name="object_distractor2_visual_p6" type="mesh" mesh="pla_block_p6" material="object_distractor2_mat" mass="0" contype="0" conaffinity="0" group="2" rgba="1 1 1 0"/>
          <geom name="object_distractor2_visual_p7" type="mesh" mesh="pla_block_p7" material="object_distractor2_mat" mass="0" contype="0" conaffinity="0" group="2" rgba="1 1 1 0"/>
          <geom name="object_distractor2_visual_p8" type="mesh" mesh="pla_block_p8" material="object_distractor2_mat" mass="0" contype="0" conaffinity="0" group="2" rgba="1 1 1 0"/>
          <geom name="object_distractor2_visual_p9" type="mesh" mesh="pla_block_p9" material="object_distractor2_mat" mass="0" contype="0" conaffinity="0" group="2" rgba="1 1 1 0"/>
          <geom name="object_distractor2_visual_p10" type="mesh" mesh="pla_block_p10" material="object_distractor2_mat" mass="0" contype="0" conaffinity="0" group="2" rgba="1 1 1 0"/>
          <geom name="object_distractor2_visual_p11" type="mesh" mesh="pla_block_p11" material="object_distractor2_mat" mass="0" contype="0" conaffinity="0" group="2" rgba="1 1 1 0"/>
          <geom name="object_distractor2_visual_p12" type="mesh" mesh="pla_block_p12" material="object_distractor2_mat" mass="0" contype="0" conaffinity="0" group="2" rgba="1 1 1 0"/>
          <geom name="object_distractor2_visual_p13" type="mesh" mesh="pla_block_p13" material="object_distractor2_mat" mass="0" contype="0" conaffinity="0" group="2" rgba="1 1 1 0"/>
          <geom name="object_distractor2_visual_p14" type="mesh" mesh="pla_block_p14" material="object_distractor2_mat" mass="0" contype="0" conaffinity="0" group="2" rgba="1 1 1 0"/>
          <site name="object_distractor2" pos="0 0 0" size="0.002 0.002 0.002" rgba="0 0 1 1" type="sphere"></site>
        </body>
        <body name="base_link" childclass="ar4_mk3">
      		  <joint armature="0.0001" axis="1 0 0" damping="1e+11" name="robot0:slide0" pos="0 0 0" type="slide"></joint>
           	<joint armature="0.0001" axis="0 1 0" damping="1e+11" name="robot0:slide1" pos="0 0 0" type="slide"></joint>
		        <joint armature="0.0001" axis="0 0 1" damping="1e+11" name="robot0:slide2" pos="0 0 0" type="slide"></joint>
            <inertial mass="0.7102" pos="-4.6941E-06 0.054174 0.038824" diaginertia="0.0039943 0.0014946 0.0042554"/>
            <geom type="mesh" mesh="base_link" contype="0" conaffinity="0" material="base_link_mat"/>
            <body name="link_1" pos="0 0 0" quat="0 1 0 0">
                <inertial pos="-0.022706 0.04294 -0.12205" quat="0.605544 0.332827 -0.00148159 0.722869" mass="0.88065"
                          diaginertia="0.00475513 0.00393687 0.0015935"/>
                <joint name="joint_1" pos="0 0 0" axis="0 0 1" range="-2.96706 2.96706" class="size5"/>
                <geom type="mesh" mesh="link_1" material="link_1_mat"/>
                <!-- arc_l1_back: shoulder harness running up link 1 and bowing
                     out behind the base of link 2. Straight fromto default;
                     runtime bows it out. -->
                <geom name="arc_l1_back_s0" type="capsule" fromto="0 0.005 -0.020 0 0.0156 -0.047" size="0.005" material="cable_mat" rgba="0.05 0.05 0.05 1" mass="0" contype="0" conaffinity="0" group="2"/>
                <geom name="arc_l1_back_s1" type="capsule" fromto="0 0.0156 -0.047 0 0.0262 -0.074" size="0.005" material="cable_mat" rgba="0.05 0.05 0.05 1" mass="0" contype="0" conaffinity="0" group="2"/>
                <geom name="arc_l1_back_s2" type="capsule" fromto="0 0.0262 -0.074 0 0.0368 -0.101" size="0.005" material="cable_mat" rgba="0.05 0.05 0.05 1" mass="0" contype="0" conaffinity="0" group="2"/>
                <geom name="arc_l1_back_s3" type="capsule" fromto="0 0.0368 -0.101 0 0.0474 -0.128" size="0.005" material="cable_mat" rgba="0.05 0.05 0.05 1" mass="0" contype="0" conaffinity="0" group="2"/>
                <geom name="arc_l1_back_s4" type="capsule" fromto="0 0.0474 -0.128 0 0.058 -0.155" size="0.005" material="cable_mat" rgba="0.05 0.05 0.05 1" mass="0" contype="0" conaffinity="0" group="2"/>
                <body name="link_2" pos="0 0.064146 -0.16608" quat="0.353551 0.612373 -0.353555 -0.612373">
                    <inertial pos="0.064818 -0.11189 -0.038671" quat="0.637507 0.725997 0.196395 0.167158"
                              mass="0.57738"
                              diaginertia="0.00602866 0.00569905 0.000699994"/>
                    <joint name="joint_2" pos="0 0 0" axis="0 0 -1" range="-0.733038 1.5708" class="size4"/>
                    <geom type="mesh" mesh="link_2" material="link_2_mat"/>
                    <!-- Wiring-harness tubes (visual only; geometry DR in
                         _sample_arm_cables toggles/recolors/jitters these per
                         episode). The DR goal is silhouette variety, not a
                         faithful copy of the real harness, so placements are
                         approximate and meant to be eyeballed. Arched cables
                         (arc_*) are chains of capsule sub-segments that the
                         runtime bends into a bow floating off the link; the
                         fromto here is just a straight default for the DR-off
                         case. arc_l2_back: link 2↔3 run bowing off the back. -->
                    <geom name="arc_l2_back_s0" type="capsule" fromto="0.010 -0.020 0 0.036 -0.065 0" size="0.005" material="cable_mat" rgba="0.05 0.05 0.05 1" mass="0" contype="0" conaffinity="0" group="2"/>
                    <geom name="arc_l2_back_s1" type="capsule" fromto="0.036 -0.065 0 0.062 -0.110 0" size="0.005" material="cable_mat" rgba="0.05 0.05 0.05 1" mass="0" contype="0" conaffinity="0" group="2"/>
                    <geom name="arc_l2_back_s2" type="capsule" fromto="0.062 -0.110 0 0.088 -0.155 0" size="0.005" material="cable_mat" rgba="0.05 0.05 0.05 1" mass="0" contype="0" conaffinity="0" group="2"/>
                    <geom name="arc_l2_back_s3" type="capsule" fromto="0.088 -0.155 0 0.114 -0.200 0" size="0.005" material="cable_mat" rgba="0.05 0.05 0.05 1" mass="0" contype="0" conaffinity="0" group="2"/>
                    <geom name="arc_l2_back_s4" type="capsule" fromto="0.114 -0.200 0 0.140 -0.245 0" size="0.005" material="cable_mat" rgba="0.05 0.05 0.05 1" mass="0" contype="0" conaffinity="0" group="2"/>
                    <!-- arc_l2_back2 / arc_l2_back3: extra bundles running the
                         length of link 2 between joints 2 and 3, offset to ±z
                         so they read as a thick multi-cable harness. -->
                    <geom name="arc_l2_back2_s0" type="capsule" fromto="0.020 -0.020 0.015 0.046 -0.065 0.015" size="0.005" material="cable_mat" rgba="0.05 0.05 0.05 1" mass="0" contype="0" conaffinity="0" group="2"/>
                    <geom name="arc_l2_back2_s1" type="capsule" fromto="0.046 -0.065 0.015 0.072 -0.110 0.015" size="0.005" material="cable_mat" rgba="0.05 0.05 0.05 1" mass="0" contype="0" conaffinity="0" group="2"/>
                    <geom name="arc_l2_back2_s2" type="capsule" fromto="0.072 -0.110 0.015 0.098 -0.155 0.015" size="0.005" material="cable_mat" rgba="0.05 0.05 0.05 1" mass="0" contype="0" conaffinity="0" group="2"/>
                    <geom name="arc_l2_back2_s3" type="capsule" fromto="0.098 -0.155 0.015 0.124 -0.200 0.015" size="0.005" material="cable_mat" rgba="0.05 0.05 0.05 1" mass="0" contype="0" conaffinity="0" group="2"/>
                    <geom name="arc_l2_back2_s4" type="capsule" fromto="0.124 -0.200 0.015 0.150 -0.245 0.015" size="0.005" material="cable_mat" rgba="0.05 0.05 0.05 1" mass="0" contype="0" conaffinity="0" group="2"/>
                    <geom name="arc_l2_back3_s0" type="capsule" fromto="0.005 -0.025 -0.015 0.0375 -0.0813 -0.015" size="0.004" material="cable_mat" rgba="0.05 0.05 0.05 1" mass="0" contype="0" conaffinity="0" group="2"/>
                    <geom name="arc_l2_back3_s1" type="capsule" fromto="0.0375 -0.0813 -0.015 0.070 -0.1375 -0.015" size="0.004" material="cable_mat" rgba="0.05 0.05 0.05 1" mass="0" contype="0" conaffinity="0" group="2"/>
                    <geom name="arc_l2_back3_s2" type="capsule" fromto="0.070 -0.1375 -0.015 0.1025 -0.1938 -0.015" size="0.004" material="cable_mat" rgba="0.05 0.05 0.05 1" mass="0" contype="0" conaffinity="0" group="2"/>
                    <geom name="arc_l2_back3_s3" type="capsule" fromto="0.1025 -0.1938 -0.015 0.135 -0.250 -0.015" size="0.004" material="cable_mat" rgba="0.05 0.05 0.05 1" mass="0" contype="0" conaffinity="0" group="2"/>
                    <body name="link_3" pos="0.1525 -0.26414 0" quat="0.258821 0 0 -0.965925">
                        <inertial pos="-0.00029765 -0.023661 -0.0019125" quat="0.624233 0.264737 -0.541021 0.497538"
                                  mass="0.1787" diaginertia="0.000217382 0.00018094 0.000106269"/>
                        <joint name="joint_3" pos="0 0 0" axis="0 0 -1" range="-1.55334 0.907571" class="size3"/>
                        <geom type="mesh" mesh="link_3" material="link_3_mat"/>
                        <!-- link 3↔4 bridge near the joint cluster. -->
                        <geom name="cable_l3_a" type="capsule" fromto="0 -0.025 -0.01 0 0.01 0.02" size="0.005" material="cable_mat" rgba="0.05 0.05 0.05 1" mass="0" contype="0" conaffinity="0" group="2"/>
                        <!-- arc_l32: bridges joint 3 — arcs across the joint
                             from link 3 back toward link 2. Parented to link 3
                             (its origin is the joint to link 2). -->
                        <geom name="arc_l32_s0" type="capsule" fromto="0.030 -0.035 0 0.015 -0.0125 0" size="0.005" material="cable_mat" rgba="0.05 0.05 0.05 1" mass="0" contype="0" conaffinity="0" group="2"/>
                        <geom name="arc_l32_s1" type="capsule" fromto="0.015 -0.0125 0 0.000 0.010 0" size="0.005" material="cable_mat" rgba="0.05 0.05 0.05 1" mass="0" contype="0" conaffinity="0" group="2"/>
                        <geom name="arc_l32_s2" type="capsule" fromto="0.000 0.010 0 -0.015 0.0325 0" size="0.005" material="cable_mat" rgba="0.05 0.05 0.05 1" mass="0" contype="0" conaffinity="0" group="2"/>
                        <geom name="arc_l32_s3" type="capsule" fromto="-0.015 0.0325 0 -0.030 0.055 0" size="0.005" material="cable_mat" rgba="0.05 0.05 0.05 1" mass="0" contype="0" conaffinity="0" group="2"/>
                        <body name="link_4" pos="0 0 0.00675" quat="0.698332 0.111048 -0.698333 -0.111048">
                            <inertial pos="-0.0016798 -0.00057319 -0.074404"
                                      quat="0.585577 0.00762899 0.0105954 0.810512"
                                      mass="0.34936" diaginertia="0.00310946 0.00304897 0.000220712"/>
                            <joint name="joint_4" pos="0 0 0" axis="0 0 -1" range="-2.87979 2.87979" class="size2"/>
                            <geom type="mesh" mesh="link_4" material="link_4_mat"/>
                            <!-- link 4↔5 main forearm run (the bulk of the
                                 harness): two arched bundles floating over the
                                 top of the link toward the wrist. fromto is a
                                 straight default; the runtime bows them out. -->
                            <geom name="arc_l4a_s0" type="capsule" fromto="0 0 -0.020 0 0 -0.057" size="0.005" material="cable_mat" rgba="0.05 0.05 0.05 1" mass="0" contype="0" conaffinity="0" group="2"/>
                            <geom name="arc_l4a_s1" type="capsule" fromto="0 0 -0.057 0 0 -0.094" size="0.005" material="cable_mat" rgba="0.05 0.05 0.05 1" mass="0" contype="0" conaffinity="0" group="2"/>
                            <geom name="arc_l4a_s2" type="capsule" fromto="0 0 -0.094 0 0 -0.131" size="0.005" material="cable_mat" rgba="0.05 0.05 0.05 1" mass="0" contype="0" conaffinity="0" group="2"/>
                            <geom name="arc_l4a_s3" type="capsule" fromto="0 0 -0.131 0 0 -0.168" size="0.005" material="cable_mat" rgba="0.05 0.05 0.05 1" mass="0" contype="0" conaffinity="0" group="2"/>
                            <geom name="arc_l4a_s4" type="capsule" fromto="0 0 -0.168 0 0 -0.205" size="0.005" material="cable_mat" rgba="0.05 0.05 0.05 1" mass="0" contype="0" conaffinity="0" group="2"/>
                            <geom name="arc_l4b_s0" type="capsule" fromto="0 0.01 -0.030 0 0.01 -0.070" size="0.004" material="cable_mat" rgba="0.05 0.05 0.05 1" mass="0" contype="0" conaffinity="0" group="2"/>
                            <geom name="arc_l4b_s1" type="capsule" fromto="0 0.01 -0.070 0 0.01 -0.110" size="0.004" material="cable_mat" rgba="0.05 0.05 0.05 1" mass="0" contype="0" conaffinity="0" group="2"/>
                            <geom name="arc_l4b_s2" type="capsule" fromto="0 0.01 -0.110 0 0.01 -0.150" size="0.004" material="cable_mat" rgba="0.05 0.05 0.05 1" mass="0" contype="0" conaffinity="0" group="2"/>
                            <geom name="arc_l4b_s3" type="capsule" fromto="0 0.01 -0.150 0 0.01 -0.190" size="0.004" material="cable_mat" rgba="0.05 0.05 0.05 1" mass="0" contype="0" conaffinity="0" group="2"/>
                            <!-- arc_l43: bridges joint 4 — runs up the forearm
                                 and arcs back across the joint toward link 3.
                                 Parented to link 4 (its origin is the joint to
                                 link 3); end reaches just past the joint. -->
                            <geom name="arc_l43_s0" type="capsule" fromto="0 0.005 -0.080 0 0.005 -0.061" size="0.005" material="cable_mat" rgba="0.05 0.05 0.05 1" mass="0" contype="0" conaffinity="0" group="2"/>
                            <geom name="arc_l43_s1" type="capsule" fromto="0 0.005 -0.061 0 0.005 -0.042" size="0.005" material="cable_mat" rgba="0.05 0.05 0.05 1" mass="0" contype="0" conaffinity="0" group="2"/>
                            <geom name="arc_l43_s2" type="capsule" fromto="0 0.005 -0.042 0 0.005 -0.023" size="0.005" material="cable_mat" rgba="0.05 0.05 0.05 1" mass="0" contype="0" conaffinity="0" group="2"/>
                            <geom name="arc_l43_s3" type="capsule" fromto="0 0.005 -0.023 0 0.005 -0.004" size="0.005" material="cable_mat" rgba="0.05 0.05 0.05 1" mass="0" contype="0" conaffinity="0" group="2"/>
                            <geom name="arc_l43_s4" type="capsule" fromto="0 0.005 -0.004 0 0.005 0.015" size="0.005" material="cable_mat" rgba="0.05 0.05 0.05 1" mass="0" contype="0" conaffinity="0" group="2"/>
                            <body name="link_5" pos="0 0 -0.22225" quat="0 0.157044 -0.987592 0">
                                <inertial pos="0.0015066 -1.3102e-05 -0.012585" quat="0.6792 0.196164 0.195898 0.679581"
                                          mass="0.11562" diaginertia="8.2921e-05 5.66869e-05 5.0866e-05"/>
                                <joint name="joint_5" pos="0 0 0" axis="1 0 0" range="-1.8326 1.8326" class="size2"/>
                                <geom type="mesh" mesh="link_5" material="link_5_mat"/>
                                <!-- link 5↔6 wrist segment. -->
                                <geom name="cable_l5_a" type="capsule" fromto="0.015 0.01 0.0 0.012 0.005 0.022" size="0.004" material="cable_mat" rgba="0.05 0.05 0.05 1" mass="0" contype="0" conaffinity="0" group="2"/>
                                <geom name="cable_l5_b" type="capsule" fromto="-0.013 0.012 -0.005 -0.01 0.006 0.02" size="0.0035" material="cable_mat" rgba="0.05 0.05 0.05 1" mass="0" contype="0" conaffinity="0" group="2"/>
                                <body name="link_6" pos="-0.000294 0 0.02117" quat="-3.67321e-06 0 0 1">
                                    <inertial pos="-0.000627476 -0.00371003 0.0349431"
                                              quat="0.447528 0.54346 0.472296 0.530383" mass="0.093863"
                                              diaginertia="5.53791e-05 4.32053e-05 3.61482e-05"/>
                                    <joint name="joint_6" pos="0 0 0" axis="0 0 1" range="-2.70526 2.70526"
                                           class="size2"/>
                                    <geom type="mesh" mesh="link_6" material="link_6_mat"/>
                                    <body name="gripper_base_link">
                                        <geom pos="0 0 0.016" quat="0.707105 -0.707108 0 0" type="mesh"
                                              mesh="gripper_base_link" material="gripper_base_link_mat"/>
                                        <body name="gripper_camera_body" pos="0.0 -0.05 0.04" quat="0 0 0.9848 -0.1736">
                                            <camera name="gripper_camera" fovy="80"/>
                                            <geom name="gripper_camera_geom" type="box" size="0.038 0.02 0.012" pos="0.0 0.01 0.0" material="black" contype="0" conaffinity="0" group="2"/>
                                            <geom name="gripper_camera_lens" type="cylinder" size="0.005 0.005" pos="0 0 -0.007" material="red" contype="0" conaffinity="0" group="2" quat="0 1 0 0"/>
                                        </body>
                                        <body name="gripper_jaw1_link" pos="0 -0.0155 0.052"
                                              quat="0.707105 -0.707108 0 0">
                                            <!-- <inertial diaginertia="0.1 0.1 0.1" mass="1" pos="0 0 0"/> -->
                                            <inertial pos="-0.00435839 -0.00469536 0.00757141"
                                                      quat="0.909592 0.206495 -0.239067 0.269904" mass="0.05"
                                                      diaginertia="1.2974e-06 1.23198e-06 8.70621e-07"/>
                                            <joint name="gripper_jaw1_joint" pos="0 0 0" axis="1 0 0" type="slide"
                        range="-0.014 0" armature="0.001" damping="50" limited="true" solimplimit="0.99 0.999 0.01" solreflimit="0.01 1" frictionloss="2" stiffness="0"/>
                                            <geom type="mesh" mesh="gripper_jaw1_link" material="gripper_jaw1_mat" contype="0" conaffinity="0" group="2"/>
                                            <geom name="gripper_jaw1_contact" size="0.001 0.0115 0.0088" pos="-0.0014 -0.0167 0.0126"
                                                  type="box" contype="1" conaffinity="1" condim="4"
                                                  solref="0.004 1" solimp="0.95 0.99 0.001 0.5 2"
                                                  friction="2.0 0.5 0.1" material="transparent"/>
                                        </body>
                                        <body name="gripper_jaw2_link" pos="0 0.0097 0.052"
                                              quat="0 0 -0.707105 0.707108">
                                            <!-- <inertial diaginertia="0.1 0.1 0.1" mass="1" pos="0 0 0"/> -->
                                            <inertial pos="-0.00423971 -0.00491236 0.00814582"
                                                      quat="0.922918 0.214097 -0.253072 0.195807" mass="0.05"
                                                      diaginertia="1.25734e-06 1.16888e-06 8.63781e-07"/>
                                            <joint name="gripper_jaw2_joint" pos="0 0 0" axis="1 0 0" type="slide"
                        range="-0.014 0" armature="0.001" damping="50" limited="true" solimplimit="0.99 0.999 0.01" solreflimit="0.01 1" frictionloss="2" stiffness="0"/>
                                            <geom type="mesh" mesh="gripper_jaw2_link" material="gripper_jaw2_mat" contype="0" conaffinity="0" group="2"/>
                                            <geom name="gripper_jaw2_contact" size="0.001 0.0115 0.0088" pos="-0.0014 -0.0167 0.0126"
                                                  type="box" contype="1" conaffinity="1" condim="4"
                                                  solref="0.004 1" solimp="0.95 0.99 0.001 0.5 2"
                                                  friction="2.0 0.5 0.1" material="transparent"/>
                                        </body>
                                        <site name="grip" pos="0 0 0.062" rgba="0 0 0 0" size="0.002" type="sphere"/>
                                    </body>
                                </body>
                            </body>
                        </body>
                    </body>
                </body>
            </body>
        </body>
    </worldbody>

    <actuator>
        <position class="position" name="act1" joint="joint_1" ctrlrange="-2.96706 2.96706"/>
        <position class="position" name="act2" joint="joint_2" ctrlrange="-0.733038 1.5708"/>
        <position class="position" name="act3" joint="joint_3" ctrlrange="-1.55334 0.907571"/>
        <position class="position" name="act4" joint="joint_4" ctrlrange="-2.87979 2.87979"/>
        <position class="position3" name="act5" joint="joint_5" ctrlrange="-1.8326 1.8326"/>
        <position class="position3" name="act6" joint="joint_6" ctrlrange="-2.70526 2.70526"/>
        <position name="act8" joint="gripper_jaw1_joint" kp="10000" ctrlrange="-0.014 0"/>
        <position name="act9" joint="gripper_jaw2_joint" kp="10000" ctrlrange="-0.014 0"/>
    </actuator>


</mujoco>
